Workbook

Sheet Cover
A1: Infosys Limited (NSE: INFY) — Three-Statement Model & DCF Valuation
A2: ₹ crore unless stated | Ind AS consolidated | Fiscal year ends 31 March | Historicals FY2022A–FY2026A, forecast FY2027E–FY2031E
A4: KEY OUTPUTS (live — change scenario in Assumptions!D4)
A5: Scenario | C5: =Assumptions!E4 -> Base case
A6: Implied value per share (₹) | C6: =DCF!D56 -> 1182.5928
A7: Current share price (₹, 22-Oct-2026 close) | C7: =DCF!D7 -> 1153.35
A8: Implied upside / (downside) | C8: =DCF!D58 -> 0.025354629
A9: Enterprise value (₹ crore) | C9: =DCF!D42 -> 429197.49
A10: Equity value at 31-Mar-2026 (₹ crore) | C10: =DCF!D51 -> 457924.49
A11: WACC | C11: =DCF!D9 -> 0.12329127
A12: Terminal growth rate | C12: =DCF!D10 -> 0.05
A13: Terminal value % of enterprise value | C13: =DCF!D43 -> 0.72918809
A14: FY2027E revenue (₹ crore) | C14: =IS!H6 -> 195934.39
A15: FY2027E EBIT margin | C15: =IS!H16 -> 0.21
A16: FY2027E diluted EPS (₹) | C16: =IS!H28 -> 77.977035
A17: Implied P/E on FY2027E EPS (x) | C17: =DCF!D60 -> 15.165911
A18: Model integrity | C18: =Checks!C3 -> ✓ ALL CHECKS PASS
A20: MODEL MAP
A21: Hist | C21: Reported Ind AS consolidated IS, BS, CF (FY22–FY26) + Q1 FY27 data; document references on the Sources tab
A22: Assumptions | C22: Scenario selector and Bear / Base / Bull driver blocks; common balance-sheet drivers
A23: IS | C23: Income statement: historical links + forecast driven by Assumptions
A24: BS | C24: Balance sheet: working capital, fixed assets, leases, equity roll-forward; cash from CF
A25: CF | C25: Cash flow statement (indirect); closing cash feeds BS
A26: WACC | C26: CAPM cost of equity, lease-based cost of debt, market-value weights
A27: DCF | C27: Unlevered FCF, terminal value, EV-to-equity bridge, three 5×5 sensitivity tables
A28: Checks | C28: Balance, cash tie-out, reported-figure reconciliation, roll-forward and valuation checks
A29: Sources | C29: Document references for every reported and market input
A30: COLOUR CONVENTIONS
A31: 1234 | C31: Blue font — hardcoded input (reported figure or assumption)
A32: 1234 | C32: Black font — formula on the same sheet
A33: 1234 | C33: Green font — link to another sheet
A34: 1234 | C34: Grey fill — editable assumption input
A35: 1234 | C35: Teal fill — key output
A37: METHODOLOGY NOTES
A38: • Revenue = prior year × (1 + constant-currency growth) × (1 + FX translation effect), separating operating growth from INR movement.
A39: • EBIT margin is the operating-margin input (company definition, before other income); other operating costs are the residual after employee costs and D&A.
A40: • UFCF = EBIT × (1 − tax) + D&A − capex − new lease (ROU) additions − increase in NWC. Leases are treated as debt-like; stock compensation is treated as a real cost (not added back).
A41: • Discounting from the 31-Mar-2026 balance sheet date using the mid-year convention; equity value is rolled forward to the valuation date at the cost of equity, less the ₹25 dividend paid in June 2026.
A42: • EV-to-equity bridge adds cash, current and non-current investments; deducts restricted cash, lease liabilities, NCI and acquisitions committed after the balance-sheet date (Optimum, Stratus).
A43: • Share price, risk-free rate, beta and ERP are market inputs or analyst assumptions (see Sources tab); the share price is from an unofficial aggregator and should be refreshed from NSE.
...

Sheet Hist
A1: Infosys Limited — Reported Consolidated Financials (Ind AS)
A2: ₹ crore unless stated | Fiscal year ends 31 March | All figures as reported in audited consolidated results (blue = reported input)
A4: Fiscal year | C4: FY2022A | D4: FY2023A | E4: FY2024A | F4: FY2025A | G4: FY2026A
A5: INCOME STATEMENT
A6: Revenue from operations | C6: 121641 | D6: 146767 | E6: 153670 | F6: 162990 | G6: 178650
A7: Employee benefit expenses | C7: 63986 | D7: 78359 | E7: 82620 | F7: 85950 | G7: 95094
A8: Cost of technical sub-contractors | C8: 12606 | D8: 14062 | E8: 12232 | F8: 12937 | G8: 15421
A9: Travel expenses | C9: 827 | D9: 1525 | E9: 1759 | F9: 1894 | G9: 2097
A10: Cost of software packages and others | C10: 6811 | D10: 10902 | E10: 13515 | F10: 15911 | G10: 15722
A11: Communication expenses | C11: 611 | D11: 713 | E11: 677 | F11: 620 | G11: 603
A12: Consultancy and professional charges | C12: 1885 | D12: 1684 | E12: 1726 | F12: 1655 | G12: 2090
A13: Other expenses | C13: 3424 | D13: 4392 | E13: 4716 | F13: 4787 | G13: 5343
A14: Depreciation and amortisation | C14: 3476 | D14: 4225 | E14: 4678 | F14: 4812 | G14: 4902
A15: Other income, net | C15: 2295 | D15: 2701 | E15: 4711 | F15: 3600 | G15: 4322
A16: Finance cost | C16: 200 | D16: 284 | E16: 470 | F16: 416 | G16: 416
A17: Exceptional item – impact of Labour Codes | C17: 0 | D17: 0 | E17: 0 | F17: 0 | G17: 1289
... A25: Stock compensation expense (per cash flow statement) | C25: 415 | D25: 519 | E25: 652 | F25: 802 | G25: 952
A27: BALANCE SHEET (as at 31 March)
A28: Non-current assets
A29: Property, plant and equipment | C29: 13075 | D29: 13346 | E29: 12370 | F29: 11778 | G29: 12651
A30: Right-of-use assets | C30: 4823 | D30: 6882 | E30: 6552 | F30: 6311 | G30: 6177
A31: Capital work-in-progress | C31: 416 | D31: 288 | E31: 293 | F31: 814 | G31: 526
A32: Goodwill | C32: 6195 | D32: 7248 | E32: 7303 | F32: 10106 | G32: 12117
A33: Other intangible assets | C33: 1707 | D33: 1749 | E33: 1397 | F33: 2766 | G33: 2825
A34: Investments (non-current) | C34: 13651 | D34: 12569 | E34: 11708 | F34: 11059 | G34: 8930
A35: Loans (non-current) | C35: 34 | D35: 39 | E35: 34 | F35: 16 | G35: 6
A36: Other financial assets (non-current) | C36: 1460 | D36: 2798 | E36: 3105 | F36: 3511 | G36: 2776
A37: Deferred tax assets (net) | C37: 1212 | D37: 1245 | E37: 454 | F37: 1108 | G37: 2264
A38: Income tax assets (non-current) | C38: 6098 | D38: 6453 | E38: 3045 | F38: 1622 | G38: 666
A39: Other non-current assets | C39: 2029 | D39: 2318 | E39: 2121 | F39: 2713 | G39: 3540
A40: Current assets
A41: Investments (current) | C41: 6673 | D41: 6909 | E41: 12915 | F41: 12482 | G41: 12950
A42: Trade receivables | C42: 22698 | D42: 25424 | E42: 30193 | F42: 31158 | G42: 35234
A43: Cash and cash equivalents | C43: 17472 | D43: 12173 | E43: 14786 | F43: 24455 | G43: 22201
A44: Loans (current) | C44: 248 | D44: 289 | E44: 248 | F44: 249 | G44: 234
A45: Other financial assets (current) | C45: 8727 | D45: 11604 | E45: 12085 | F45: 13840 | G45: 15890
A46: Income tax assets (current) | C46: 54 | D46: 6 | E46: 6397 | F46: 2975 | G46: 1835
A47: Other current assets | C47: 11313 | D47: 14476 | E47: 12808 | F47: 11940 | G47: 15145
A48: Total assets (reported) | C48: 117885 | D48: 125816 | E48: 137814 | F48: 148903 | G48: 155967
A49: Equity
...

Sheet Assumptions
A1: Infosys Limited — Forecast Assumptions
A2: ₹ crore unless stated | Blue = editable input; black = formula; C:G show historical actuals for reference
A4: Scenario selector (1 = Bear, 2 = Base, 3 = Bull) | D4: 2 | E4: =CHOOSE($D$4,"Bear case","Base case","Bull case") -> Base case
A6: Live case drivers (feed the model) | C6: FY2022A | D6: FY2023A | E6: FY2024A | F6: FY2025A | G6: FY2026A | H6: FY2027E | I6: FY2028E | J6: FY2029E | K6: FY2030E | L6: FY2031E
A7: Revenue & operating drivers (scenario-dependent)
A8: Constant-currency revenue growth | G8: =Hist!C93 -> 0.031 | H8: =CHOOSE($D$4,H34,H45,H56) -> 0.025 | I8: =CHOOSE($D$4,I34,I45,I56) -> 0.05 | J8: =CHOOSE($D$4,J34,J45,J56) -> 0.06 | K8: =CHOOSE($D$4,K34,K45,K56) -> 0.06 | L8: =CHOOSE($D$4,L34,L45,L56) -> 0.055
A9: FX translation effect (INR vs basket) | H9: =CHOOSE($D$4,H35,H46,H57) -> 0.07 | I9: =CHOOSE($D$4,I35,I46,I57) -> 0.025 | J9: =CHOOSE($D$4,J35,J46,J57) -> 0.025 | K9: =CHOOSE($D$4,K35,K46,K57) -> 0.025 | L9: =CHOOSE($D$4,L35,L46,L57) -> 0.025
A10: Revenue growth in INR (reported) | D10: =IS!D7 -> 0.20655864 | E10: =IS!E7 -> 0.047033734 | F10: =IS!F7 -> 0.060649444 | G10: =IS!G7 -> 0.096079514 | H10: =(1+H8)*(1+H9)-1 -> 0.09675 | I10: =(1+I8)*(1+I9)-1 -> 0.07625 | J10: =(1+J8)*(1+J9)-1 -> 0.0865 | K10: =(1+K8)*(1+K9)-1 -> 0.0865 | L10: =(1+L8)*(1+L9)-1 -> 0.081375
A11: Employee benefit expenses % revenue | C11: =IS!C9 -> 0.5260233 | D11: =IS!D9 -> 0.53390067 | E11: =IS!E9 -> 0.5376456 | F11: =IS!F9 -> 0.52733297 | G11: =IS!G9 -> 0.53229219 | H11: =CHOOSE($D$4,H36,H47,H58) -> 0.53 | I11: =CHOOSE($D$4,I36,I47,I58) -> 0.528 | J11: =CHOOSE($D$4,J36,J47,J58) -> 0.526 | K11: =CHOOSE($D$4,K36,K47,K58) -> 0.525 | L11: =CHOOSE($D$4,L36,L47,L58) -> 0.525
A12: EBIT (operating) margin | C12: =IS!C16 -> 0.23030886 | D12: =IS!D16 -> 0.21057186 | E12: =IS!E16 -> 0.20659205 | F12: =IS!F16 -> 0.21120314 | G12: =IS!G16 -> 0.20922474 | H12: =CHOOSE($D$4,H37,H48,H59) -> 0.21 | I12: =CHOOSE($D$4,I37,I48,I59) -> 0.21 | J12: =CHOOSE($D$4,J37,J48,J59) -> 0.212 | K12: =CHOOSE($D$4,K37,K48,K59) -> 0.213 | L12: =CHOOSE($D$4,L37,L48,L59) -> 0.213
A13: D&A % revenue | C13: =IS!C14/IS!C6 -> 0.028575891 | D13: =IS!D14/IS!D6 -> 0.028787125 | E13: =IS!E14/IS!E6 -> 0.030441856 | F13: =IS!F14/IS!F6 -> 0.029523284 | G13: =IS!G14/IS!G6 -> 0.027439127 | H13: =CHOOSE($D$4,H38,H49,H60) -> 0.028 | I13: =CHOOSE($D$4,I38,I49,I60) -> 0.028 | J13: =CHOOSE($D$4,J38,J49,J60) -> 0.028 | K13: =CHOOSE($D$4,K38,K49,K60) -> 0.028 | L13: =CHOOSE($D$4,L38,L49,L60) -> 0.028
A14: Capex % revenue | C14: =-CF!C17/IS!C6 -> 0.017765392 | D14: =-CF!D17/IS!D6 -> 0.01757207 | E14: =-CF!E17/IS!E6 -> 0.0143229 | F14: =-CF!F17/IS!F6 -> 0.013724768 | G14: =-CF!G17/IS!G6 -> 0.015264484 | H14: =CHOOSE($D$4,H39,H50,H61) -> 0.016 | I14: =CHOOSE($D$4,I39,I50,I61) -> 0.016 | J14: =CHOOSE($D$4,J39,J50,J61) -> 0.016 | K14: =CHOOSE($D$4,K39,K50,K61) -> 0.016 | L14: =CHOOSE($D$4,L39,L50,L61) -> 0.016
A15: Trade receivable days (DSO) | C15: =BS!C38 -> 68.108368 | D15: =BS!D38 -> 63.227837 | E15: =BS!E38 -> 71.715006 | F15: =BS!F38 -> 69.775262 | G15: =BS!G38 -> 71.986622 | H15: =CHOOSE($D$4,H40,H51,H62) -> 72 | I15: =CHOOSE($D$4,I40,I51,I62) -> 72 | J15: =CHOOSE($D$4,J40,J51,J62) -> 72 | K15: =CHOOSE($D$4,K40,K51,K62) -> 72 | L15: =CHOOSE($D$4,L40,L51,L62) -> 72
A16: Effective tax rate | C16: =IS!C22 -> 0.26449684 | D16: =IS!D22 -> 0.27651401 | E16: =IS!E22 -> 0.27064577 | F16: =IS!F22 -> 0.28871517 | G16: =IS!G22 -> 0.26305788 | H16: =CHOOSE($D$4,H41,H52,H63) -> 0.275 | I16: =CHOOSE($D$4,I41,I52,I63) -> 0.275 | J16: =CHOOSE($D$4,J41,J52,J63) -> 0.275 | K16: =CHOOSE($D$4,K41,K52,K63) -> 0.275 | L16: =CHOOSE($D$4,L41,L52,L63) -> 0.275
A18: Other operating & balance-sheet drivers (all scenarios)
A19: Stock compensation % revenue (non-cash, within employee cost) | C19: =IS!C29/IS!C6 -> 0.0034116786 | D19: =IS!D29/IS!D6 -> 0.0035362173 | E19: =IS!E29/IS!E6 -> 0.0042428581 | F19: =IS!F29/IS!F6 -> 0.0049205473 | G19: =IS!G29/IS!G6 -> 0.0053288553 | H19: 0.0055 | I19: 0.0055 | J19: 0.0055 | K19: 0.0055 | L19: 0.0055
A20: Other current assets % revenue (unbilled, loans, other) | C20: =BS!C10/IS!C6 -> 0.16678587 | D20: =BS!D10/IS!D6 -> 0.17966573 | E20: =BS!E10/IS!E6 -> 0.16360383 | F20: =BS!F10/IS!F6 -> 0.15969691 | G20: =BS!G10/IS!G6 -> 0.17502939 | H20: 0.175 | I20: 0.175 | J20: 0.175 | K20: 0.175 | L20: 0.175
A21: Trade payables % revenue | C21: =BS!C18/IS!C6 -> 0.033985252 | D21: =BS!D18/IS!D6 -> 0.026334258 | E21: =BS!E18/IS!E6 -> 0.025743476 | F21: =BS!F18/IS!F6 -> 0.02554758 | G21: =BS!G18/IS!G6 -> 0.026554716 | H21: 0.027 | I21: 0.027 | J21: 0.027 | K21: 0.027 | L21: 0.027
A22: Other current liabilities & provisions % revenue | C22: =BS!C19/IS!C6 -> 0.21366151 | D22: =BS!D19/IS!D6 -> 0.20914102 | E22: =BS!E19/IS!E6 -> 0.19062927 | F22: =BS!F19/IS!F6 -> 0.19251488 | G22: =BS!G19/IS!G6 -> 0.2170389 | H22: 0.217 | I22: 0.217 | J22: 0.217 | K22: 0.217 | L22: 0.217
A23: Lease liabilities % revenue | C23: =BS!C21/IS!C6 -> 0.045001274 | D23: =BS!D21/IS!D6 -> 0.056545409 | E23: =BS!E21/IS!E6 -> 0.054395783 | F23: =BS!F21/IS!F6 -> 0.050475489 | G23: =BS!G21/IS!G6 -> 0.051363 | H23: 0.051 | I23: 0.051 | J23: 0.051 | K23: 0.051 | L23: 0.051
A24: Lease principal repayment % revenue | C24: =-CF!C23/IS!C6 -> 0.0075221348 | D24: =-CF!D23/IS!D6 -> 0.008387444 | E24: =-CF!E23/IS!E6 -> 0.013171081 | F24: =-CF!F23/IS!F6 -> 0.014448739 | G24: =-CF!G23/IS!G6 -> 0.015807445 | H24: 0.016 | I24: 0.016 | J24: 0.016 | K24: 0.016 | L24: 0.016
A25: Yield on opening cash & investments (other income) | D25: =IS!D17/(BS!C6+BS!C7+BS!C8) -> 0.071462589 | E25: =IS!E17/(BS!D6+BS!D7+BS!D8) -> 0.14884206 | F25: =IS!F17/(BS!E6+BS!E7+BS!E8) -> 0.091349692 | G25: =IS!G17/(BS!F6+BS!F7+BS!F8) -> 0.090049171 | H25: 0.067 | I25: 0.067 | J25: 0.067 | K25: 0.067 | L25: 0.067
A26: Finance cost % opening lease liabilities | D26: =IS!D18/BS!C21 -> 0.051881622 | E26: =IS!E18/BS!D21 -> 0.056633329 | F26: =IS!F18/BS!E21 -> 0.049766719 | G26: =IS!G18/BS!F21 -> 0.050565212 | H26: 0.05 | I26: 0.05 | J26: 0.05 | K26: 0.05 | L26: 0.05
A27: Non-controlling interests share of profit | C27: =IS!C24/IS!C23 -> 0.0016255757 | D27: =IS!D24/IS!D23 -> 0.00053924009 | E27: =IS!E24/IS!E23 -> 0.00057147211 | F27: =IS!F24/IS!F23 -> 0.0013831776 | G27: =IS!G24/IS!G23 -> 0.0011535591 | H27: 0.0012 | I27: 0.0012 | J27: 0.0012 | K27: 0.0012 | L27: 0.0012
A28: Dividends paid % of net profit to owners | C28: =-CF!C24/IS!C25 -> 0.5758028 | D28: =-CF!D24/IS!D25 -> 0.56663208 | E28: =-CF!E24/IS!E25 -> 0.56154462 | F28: =-CF!F24/IS!F25 -> 0.75951784 | G28: =-CF!G24/IS!G25 -> 0.63369565 | H28: 0.7 | I28: 0.7 | J28: 0.7 | K28: 0.7 | L28: 0.7
A29: Share buybacks (₹ crore) | C29: =-CF!C25 -> 11125 | D29: =-CF!D25 -> 11499 | E29: =-CF!E25 -> 0 | F29: =-CF!F25 -> 0 | G29: =-CF!G25 -> 18058 | H29: 0 | I29: 0 | J29: 0 | K29: 0 | L29: 0
A30: Acquisitions, cash (₹ crore) | C30: =-CF!C18 -> 53 | D30: =-CF!D18 -> 970 | E30: =-CF!E18 -> 101 | F30: =-CF!F18 -> 3155 | G30: =-CF!G18 -> 650 | H30: =Hist!C94+Hist!C95 -> 5311 | I30: 0 | J30: 0 | K30: 0 | L30: 0
A31: Diluted shares outstanding (crore) | C31: =IS!C27 -> 421.86606 | D31: =IS!D27 -> 418.75217 | E31: =IS!E27 -> 414.48886 | F31: =IS!F27 -> 415.18495 | G31: =IS!G27 -> 411.97873 | H31: =Hist!$C$87-H29/DCF!$D$7 -> 405.26865 | I31: =H31-I29/DCF!$D$7 -> 405.26865 | J31: =I31-J29/DCF!$D$7 -> 405.26865 | K31: =J31-K29/DCF!$D$7 -> 405.26865 | L31: =K31-L29/DCF!$D$7 -> 405.26865
A32: BEAR CASE ASSUMPTIONS
A33: Assumption | H33: FY2027E | I33: FY2028E | J33: FY2029E | K33: FY2030E | L33: FY2031E
A34: Constant-currency revenue growth | H34: 0.015 | I34: 0.025 | J34: 0.035 | K34: 0.04 | L34: 0.04
A35: FX translation effect (INR vs basket) | H35: 0.06 | I35: 0.01 | J35: 0.01 | K35: 0.01 | L35: 0.01
A36: Employee benefit expenses % revenue | H36: 0.535 | I36: 0.538 | J36: 0.54 | K36: 0.54 | L36: 0.54
A37: EBIT (operating) margin | H37: 0.2 | I37: 0.198 | J37: 0.195 | K37: 0.195 | L37: 0.195
A38: D&A % revenue | H38: 0.029 | I38: 0.029 | J38: 0.029 | K38: 0.029 | L38: 0.029
A39: Capex % revenue | H39: 0.018 | I39: 0.018 | J39: 0.018 | K39: 0.018 | L39: 0.018
A40: Trade receivable days (DSO) | H40: 76 | I40: 76 | J40: 76 | K40: 76 | L40: 76
A41: Effective tax rate | H41: 0.285 | I41: 0.285 | J41: 0.285 | K41: 0.285 | L41: 0.285
A43: BASE CASE ASSUMPTIONS
A44: Assumption | H44: FY2027E | I44: FY2028E | J44: FY2029E | K44: FY2030E | L44: FY2031E
...

Sheet IS
A1: Infosys Limited — Consolidated Income Statement
A2: ="₹ crore unless stated | Ind AS | FY ends 31 March | Forecast case: "&Assumptions!$E$4 -> ₹ crore unless stated | Ind AS | FY ends 31 March | Forecast case: Base case
A4: Fiscal year | C4: FY2022A | D4: FY2023A | E4: FY2024A | F4: FY2025A | G4: FY2026A | H4: FY2027E | I4: FY2028E | J4: FY2029E | K4: FY2030E | L4: FY2031E
A6: Revenue from operations | C6: =Hist!C6 -> 121641 | D6: =Hist!D6 -> 146767 | E6: =Hist!E6 -> 153670 | F6: =Hist!F6 -> 162990 | G6: =Hist!G6 -> 178650 | H6: =G6*(1+Assumptions!H10) -> 195934.39 | I6: =H6*(1+Assumptions!I10) -> 210874.38 | J6: =I6*(1+Assumptions!J10) -> 229115.02 | K6: =J6*(1+Assumptions!K10) -> 248933.47 | L6: =K6*(1+Assumptions!L10) -> 269190.43
A7: Growth % | D7: =D6/C6-1 -> 0.20655864 | E7: =E6/D6-1 -> 0.047033734 | F7: =F6/E6-1 -> 0.060649444 | G7: =G6/F6-1 -> 0.096079514 | H7: =H6/G6-1 -> 0.09675 | I7: =I6/H6-1 -> 0.07625 | J7: =J6/I6-1 -> 0.0865 | K7: =K6/J6-1 -> 0.0865 | L7: =L6/K6-1 -> 0.081375
A8: Employee benefit expenses | C8: =Hist!C7 -> 63986 | D8: =Hist!D7 -> 78359 | E8: =Hist!E7 -> 82620 | F8: =Hist!F7 -> 85950 | G8: =Hist!G7 -> 95094 | H8: =H6*Assumptions!H11 -> 103845.23 | I8: =I6*Assumptions!I11 -> 111341.68 | J8: =J6*Assumptions!J11 -> 120514.5 | K8: =K6*Assumptions!K11 -> 130690.07 | L8: =L6*Assumptions!L11 -> 141324.98
A9: % of revenue | C9: =C8/C6 -> 0.5260233 | D9: =D8/D6 -> 0.53390067 | E9: =E8/E6 -> 0.5376456 | F9: =F8/F6 -> 0.52733297 | G9: =G8/G6 -> 0.53229219 | H9: =H8/H6 -> 0.53 | I9: =I8/I6 -> 0.528 | J9: =J8/J6 -> 0.526 | ... L9: =L8/L6 -> 0.525
A10: Other operating expenses (sub-contractors, travel, software, other) | C10: =SUM(Hist!C8:C13) -> 26164 | D10: =SUM(Hist!D8:D13) -> 33278 | E10: =SUM(Hist!E8:E13) -> 34625 | F10: =SUM(Hist!F8:F13) -> 37804 | G10: =SUM(Hist!G8:G13) -> 41276 | H10: =H6*(1-Assumptions!H11-Assumptions!H12-Assumptions!H13) -> 45456.778 | I10: =I6*(1-Assumptions!I11-Assumptions!I12-Assumptions!I13) -> 49344.606 | J10: =J6*(1-Assumptions!J11-Assumptions!J12-Assumptions!J13) -> 53612.914 | K10: =K6*(1-Assumptions!K11-Assumptions!K12-Assumptions!K13) -> 58250.431 | L10: =L6*(1-Assumptions!L11-Assumptions!L12-Assumptions!L13) -> 62990.56
A11: % of revenue | C11: =C10/C6 -> 0.21509195 | D11: =D10/D6 -> 0.22674034 | E11: =E10/E6 -> 0.22532049 | F11: =F10/F6 -> 0.23194061 | G11: =G10/G6 -> 0.23104394 | H11: =H10/H6 -> 0.232 | I11: =I10/I6 -> 0.234 | J11: =J10/J6 -> 0.234 | ... L11: =L10/L6 -> 0.234
A12: EBITDA | C12: =C6-C8-C10 -> 31491 | D12: =D6-D8-D10 -> 35130 | E12: =E6-E8-E10 -> 36425 | F12: =F6-F8-F10 -> 39236 | G12: =G6-G8-G10 -> 42280 | H12: =H6-H8-H10 -> 46632.384 | I12: =I6-I8-I10 -> 50188.104 | J12: =J6-J8-J10 -> 54987.605 | ... L12: =L6-L8-L10 -> 64874.893
A13: EBITDA margin | C13: =C12/C6 -> 0.25888475 | D13: =D12/D6 -> 0.23935898 | E13: =E12/E6 -> 0.2370339 | F13: =F12/F6 -> 0.24072642 | G13: =G12/G6 -> 0.23666387 | H13: =H12/H6 -> 0.238 | I13: =I12/I6 -> 0.238 | J13: =J12/J6 -> 0.24 | ... L13: =L12/L6 -> 0.241
A14: Depreciation and amortisation | C14: =Hist!C14 -> 3476 | D14: =Hist!D14 -> 4225 | E14: =Hist!E14 -> 4678 | F14: =Hist!F14 -> 4812 | G14: =Hist!G14 -> 4902 | H14: =H6*Assumptions!H13 -> 5486.1628 | I14: =I6*Assumptions!I13 -> 5904.4828 | J14: =J6*Assumptions!J13 -> 6415.2205 | K14: =K6*Assumptions!K13 -> 6970.1371 | L14: =L6*Assumptions!L13 -> 7537.332
A15: EBIT (operating profit, pre-exceptional) | C15: =C12-C14 -> 28015 | D15: =D12-D14 -> 30905 | E15: =E12-E14 -> 31747 | F15: =F12-F14 -> 34424 | G15: =G12-G14 -> 37378 | H15: =H12-H14 -> 41146.221 | I15: =I12-I14 -> 44283.621 | J15: =J12-J14 -> 48572.384 | ... L15: =L12-L14 -> 57337.561
A16: EBIT margin | C16: =C15/C6 -> 0.23030886 | D16: =D15/D6 -> 0.21057186 | E16: =E15/E6 -> 0.20659205 | F16: =F15/F6 -> 0.21120314 | G16: =G15/G6 -> 0.20922474 | H16: =H15/H6 -> 0.21 | I16: =I15/I6 -> 0.21 | J16: =J15/J6 -> 0.212 | ... L16: =L15/L6 -> 0.213
A17: Other income, net | C17: =Hist!C15 -> 2295 | D17: =Hist!D15 -> 2701 | E17: =Hist!E15 -> 4711 | F17: =Hist!F15 -> 3600 | G17: =Hist!G15 -> 4322 | H17: =(BS!G6+BS!G7+BS!G8)*Assumptions!H25 -> 2953.427 | I17: =(BS!H6+BS!H7+BS!H8)*Assumptions!I25 -> 3111.2633 | J17: =(BS!I6+BS!I7+BS!I8)*Assumptions!J25 -> 3689.3647 | K17: =(BS!J6+BS!J7+BS!J8)*Assumptions!K25 -> 4311.4998 | L17: =(BS!K6+BS!K7+BS!K8)*Assumptions!L25 -> 4995.5152
A18: Finance cost | C18: =Hist!C16 -> 200 | D18: =Hist!D16 -> 284 | E18: =Hist!E16 -> 470 | F18: =Hist!F16 -> 416 | G18: =Hist!G16 -> 416 | H18: =BS!G21*Assumptions!H26 -> 458.8 | I18: =BS!H21*Assumptions!I26 -> 499.63269 | J18: =BS!I21*Assumptions!J26 -> 537.72968 | K18: =BS!J21*Assumptions!K26 -> 584.2433 | L18: =BS!K21*Assumptions!L26 -> 634.78034
A19: Exceptional item (Labour Codes) | C19: =Hist!C17 -> 0 | D19: =Hist!D17 -> 0 | E19: =Hist!E17 -> 0 | F19: =Hist!F17 -> 0 | G19: =Hist!G17 -> 1289 | H19: 0 | I19: 0 | J19: 0 | K19: 0 | L19: 0
A20: Profit before tax | C20: =C15+C17-C18-C19 -> 30110 | D20: =D15+D17-D18-D19 -> 33322 | E20: =E15+E17-E18-E19 -> 35988 | F20: =F15+F17-F18-F19 -> 37608 | G20: =G15+G17-G18-G19 -> 39995 | H20: =H15+H17-H18-H19 -> 43640.848 | I20: =I15+I17-I18-I19 -> 46895.251 | J20: =J15+J17-J18-J19 -> 51724.019 | ... L20: =L15+L17-L18-L19 -> 61698.296
A21: Tax expense | C21: =Hist!C19+Hist!C20 -> 7964 | D21: =Hist!D19+Hist!D20 -> 9214 | E21: =Hist!E19+Hist!E20 -> 9740 | F21: =Hist!F19+Hist!F20 -> 10858 | G21: =Hist!G19+Hist!G20 -> 10521 | H21: =H20*Assumptions!H16 -> 12001.233 | I21: =I20*Assumptions!I16 -> 12896.194 | J21: =J20*Assumptions!J16 -> 14224.105 | K21: =K20*Assumptions!K16 -> 15606.273 | L21: =L20*Assumptions!L16 -> 16967.031
A22: Effective tax rate | C22: =C21/C20 -> 0.26449684 | D22: =D21/D20 -> 0.27651401 | E22: =E21/E20 -> 0.27064577 | F22: =F21/F20 -> 0.28871517 | G22: =G21/G20 -> 0.26305788 | H22: =H21/H20 -> 0.275 | I22: =I21/I20 -> 0.275 | J22: =J21/J20 -> 0.275 | ... L22: =L21/L20 -> 0.275
A23: Profit for the year | C23: =C20-C21 -> 22146 | D23: =D20-D21 -> 24108 | E23: =E20-E21 -> 26248 | F23: =F20-F21 -> 26750 | G23: =G20-G21 -> 29474 | H23: =H20-H21 -> 31639.615 | I23: =I20-I21 -> 33999.057 | J23: =J20-J21 -> 37499.914 | ... L23: =L20-L21 -> 44731.265
A24: Less: non-controlling interests | C24: =Hist!C22 -> 36 | D24: =Hist!D22 -> 13 | E24: =Hist!E22 -> 15 | F24: =Hist!F22 -> 37 | G24: =Hist!G22 -> 34 | H24: =H23*Assumptions!H27 -> 37.967538 | I24: =I23*Assumptions!I27 -> 40.798869 | J24: =J23*Assumptions!J27 -> 44.999897 | K24: =K23*Assumptions!K27 -> 49.372574 | L24: =L23*Assumptions!L27 -> 53.677518
A25: Net profit attributable to owners | C25: =C23-C24 -> 22110 | D25: =D23-D24 -> 24095 | E25: =E23-E24 -> 26233 | F25: =F23-F24 -> 26713 | G25: =G23-G24 -> 29440 | H25: =H23-H24 -> 31601.648 | I25: =I23-I24 -> 33958.258 | J25: =J23-J24 -> 37454.914 | ... L25: =L23-L24 -> 44677.587
A26: Net margin | C26: =C25/C6 -> 0.18176437 | D26: =D25/D6 -> 0.16417178 | E26: =E25/E6 -> 0.17070996 | F26: =F25/F6 -> 0.16389349 | G26: =G25/G6 -> 0.16479149 | H26: =H25/H6 -> 0.16128689 | I26: =I25/I6 -> 0.16103548 | J26: =J25/J6 -> 0.16347647 | ... L26: =L25/L6 -> 0.16597019
A27: Diluted shares (crore) | C27: =Hist!C23/Hist!C24 -> 421.86606 | D27: =Hist!D23/Hist!D24 -> 418.75217 | E27: =Hist!E23/Hist!E24 -> 414.48886 | F27: =Hist!F23/Hist!F24 -> 415.18495 | G27: =Hist!G23/Hist!G24 -> 411.97873 | H27: =Assumptions!H31 -> 405.26865 | I27: =Assumptions!I31 -> 405.26865 | J27: =Assumptions!J31 -> 405.26865 | K27: =Assumptions!K31 -> 405.26865 | L27: =Assumptions!L31 -> 405.26865
A28: Diluted EPS (₹) | C28: =Hist!C24 -> 52.41 | D28: =Hist!D24 -> 57.54 | E28: =Hist!E24 -> 63.29 | F28: =Hist!F24 -> 64.34 | G28: =Hist!G24 -> 71.46 | H28: =H25/H27 -> 77.977035 | I28: =I25/I27 -> 83.79197 | J28: =J25/J27 -> 92.419964 | K28: =K25/K27 -> 101.40049 | L28: =L25/L27 -> 110.2419
A29: Memo: stock compensation (non-cash, in employee cost) | C29: =Hist!C25 -> 415 | D29: =Hist!D25 -> 519 | E29: =Hist!E25 -> 652 | F29: =Hist!F25 -> 802 | G29: =Hist!G25 -> 952 | H29: =H6*Assumptions!H19 -> 1077.6391 | I29: =I6*Assumptions!I19 -> 1159.8091 | J29: =J6*Assumptions!J19 -> 1260.1326 | K29: =K6*Assumptions!K19 -> 1369.1341 | L29: =L6*Assumptions!L19 -> 1480.5474
A30: Memo: reported PBT check (model − reported) | C30: =C20-Hist!C18 -> 0 | D30: =D20-Hist!D18 -> 0 | E30: =E20-Hist!E18 -> 0 | F30: =F20-Hist!F18 -> 0 | G30: =G20-Hist!G18 -> 0

Sheet BS
A1: Infosys Limited — Consolidated Balance Sheet (as at 31 March)
A2: ="₹ crore | Ind AS line items grouped for forecasting | Forecast case: "&Assumptions!$E$4 -> ₹ crore | Ind AS line items grouped for forecasting | Forecast case: Base case
A4: Fiscal year | C4: FY2022A | D4: FY2023A | E4: FY2024A | F4: FY2025A | G4: FY2026A | H4: FY2027E | I4: FY2028E | J4: FY2029E | K4: FY2030E | L4: FY2031E
A5: ASSETS
A6: Cash and cash equivalents | C6: =Hist!C43 -> 17472 | D6: =Hist!D43 -> 12173 | E6: =Hist!E43 -> 14786 | F6: =Hist!F43 -> 24455 | G6: =Hist!G43 -> 22201 | H6: =CF!H31 -> 24556.765 | I6: =CF!I31 -> 33185.145 | J6: =CF!J31 -> 42470.743 | K6: =CF!K31 -> 52679.928 | L6: =CF!L31 -> 63942.504
A7: Current investments | C7: =Hist!C41 -> 6673 | D7: =Hist!D41 -> 6909 | E7: =Hist!E41 -> 12915 | F7: =Hist!F41 -> 12482 | G7: =Hist!G41 -> 12950 | H7: =G7 -> 12950 | I7: =H7 -> 12950 | J7: =I7 -> 12950 | K7: =J7 -> 12950 | L7: =K7 -> 12950
A8: Non-current investments | C8: =Hist!C34 -> 13651 | D8: =Hist!D34 -> 12569 | E8: =Hist!E34 -> 11708 | F8: =Hist!F34 -> 11059 | G8: =Hist!G34 -> 8930 | H8: =G8 -> 8930 | I8: =H8 -> 8930 | J8: =I8 -> 8930 | K8: =J8 -> 8930 | L8: =K8 -> 8930
A9: Trade receivables | C9: =Hist!C42 -> 22698 | D9: =Hist!D42 -> 25424 | E9: =Hist!E42 -> 30193 | F9: =Hist!F42 -> 31158 | G9: =Hist!G42 -> 35234 | H9: =IS!H6*Assumptions!H15/365 -> 38650.071 | I9: =IS!I6*Assumptions!I15/365 -> 41597.139 | J9: =IS!J6*Assumptions!J15/365 -> 45195.291 | K9: =IS!K6*Assumptions!K15/365 -> 49104.684 | L9: =IS!L6*Assumptions!L15/365 -> 53100.578
A10: Other current assets (unbilled, loans, other financial & other) | C10: =Hist!C44+Hist!C45+Hist!C47 -> 20288 | D10: =Hist!D44+Hist!D45+Hist!D47 -> 26369 | E10: =Hist!E44+Hist!E45+Hist!E47 -> 25141 | F10: =Hist!F44+Hist!F45+Hist!F47 -> 26029 | G10: =Hist!G44+Hist!G45+Hist!G47 -> 31269 | H10: =IS!H6*Assumptions!H20 -> 34288.518 | I10: =IS!I6*Assumptions!I20 -> 36903.017 | J10: =IS!J6*Assumptions!J20 -> 40095.128 | K10: =IS!K6*Assumptions!K20 -> 43563.357 | L10: =IS!L6*Assumptions!L20 -> 47108.325
A11: Income tax assets (current + non-current) | C11: =Hist!C46+Hist!C38 -> 6152 | D11: =Hist!D46+Hist!D38 -> 6459 | E11: =Hist!E46+Hist!E38 -> 9442 | F11: =Hist!F46+Hist!F38 -> 4597 | G11: =Hist!G46+Hist!G38 -> 2501 | H11: =G11 -> 2501 | I11: =H11 -> 2501 | J11: =I11 -> 2501 | K11: =J11 -> 2501 | L11: =K11 -> 2501
A12: PP&E, CWIP, right-of-use & other intangibles | C12: =Hist!C29+Hist!C30+Hist!C31+Hist!C33 -> 20021 | D12: =Hist!D29+Hist!D30+Hist!D31+Hist!D33 -> 22265 | E12: =Hist!E29+Hist!E30+Hist!E31+Hist!E33 -> 20612 | F12: =Hist!F29+Hist!F30+Hist!F31+Hist!F33 -> 21669 | G12: =Hist!G29+Hist!G30+Hist!G31+Hist!G33 -> 22179 | H12: =G12-CF!H17+H36-IS!H14 -> 23779.391 | I12: =H12-CF!I17+I36-IS!I14 -> 25384.829 | J12: =I12-CF!J17+J36-IS!J14 -> 27231.561 | K12: =J12-CF!K17+K36-IS!K14 -> 29238.036 | L12: =K12-CF!L17+L36-IS!L14 -> 31347.903
A13: Goodwill | C13: =Hist!C32 -> 6195 | D13: =Hist!D32 -> 7248 | E13: =Hist!E32 -> 7303 | F13: =Hist!F32 -> 10106 | G13: =Hist!G32 -> 12117 | H13: =G13-CF!H18 -> 17428 | I13: =H13-CF!I18 -> 17428 | J13: =I13-CF!J18 -> 17428 | K13: =J13-CF!K18 -> 17428 | L13: =K13-CF!L18 -> 17428
A14: Other non-current assets (loans, financial, DTA, other) | C14: =Hist!C35+Hist!C36+Hist!C37+Hist!C39 -> 4735 | D14: =Hist!D35+Hist!D36+Hist!D37+Hist!D39 -> 6400 | E14: =Hist!E35+Hist!E36+Hist!E37+Hist!E39 -> 5714 | F14: =Hist!F35+Hist!F36+Hist!F37+Hist!F39 -> 7348 | G14: =Hist!G35+Hist!G36+Hist!G37+Hist!G39 -> 8586 | H14: =G14 -> 8586 | I14: =H14 -> 8586 | J14: =I14 -> 8586 | K14: =J14 -> 8586 | L14: =K14 -> 8586
A15: Total assets | C15: =SUM(C6:C14) -> 117885 | D15: =SUM(D6:D14) -> 125816 | E15: =SUM(E6:E14) -> 137814 | F15: =SUM(F6:F14) -> 148903 | G15: =SUM(G6:G14) -> 155967 | H15: =SUM(H6:H14) -> 171669.75 | I15: =SUM(I6:I14) -> 187465.13 | J15: =SUM(J6:J14) -> 205387.72 | ... L15: =SUM(L6:L14) -> 245894.31
A17: LIABILITIES
A18: Trade payables | C18: =Hist!C60 -> 4134 | D18: =Hist!D60 -> 3865 | E18: =Hist!E60 -> 3956 | F18: =Hist!F60 -> 4164 | G18: =Hist!G60 -> 4744 | H18: =IS!H6*Assumptions!H21 -> 5290.2285 | I18: =IS!I6*Assumptions!I21 -> 5693.6084 | J18: =IS!J6*Assumptions!J21 -> 6186.1055 | K18: =IS!K6*Assumptions!K21 -> 6721.2036 | L18: =IS!L6*Assumptions!L21 -> 7268.1416
A19: Other current liabilities & provisions | C19: =Hist!C61+Hist!C62+Hist!C63 -> 25990 | D19: =Hist!D61+Hist!D62+Hist!D63 -> 30695 | E19: =Hist!E61+Hist!E62+Hist!E63 -> 29294 | F19: =Hist!F61+Hist!F62+Hist!F63 -> 31378 | G19: =Hist!G61+Hist!G62+Hist!G63 -> 38774 | H19: =IS!H6*Assumptions!H22 -> 42517.762 | I19: =IS!I6*Assumptions!I22 -> 45759.741 | J19: =IS!J6*Assumptions!J22 -> 49717.959 | K19: =IS!K6*Assumptions!K22 -> 54018.563 | L19: =IS!L6*Assumptions!L22 -> 58414.323
A20: Income tax liabilities (net) | C20: =Hist!C64 -> 2607 | D20: =Hist!D64 -> 3384 | E20: =Hist!E64 -> 3585 | F20: =Hist!F64 -> 4853 | G20: =Hist!G64 -> 5644 | H20: =G20 -> 5644 | I20: =H20 -> 5644 | J20: =I20 -> 5644 | K20: =J20 -> 5644 | L20: =K20 -> 5644
A21: Lease liabilities (current + non-current) | C21: =Hist!C54+Hist!C59 -> 5474 | D21: =Hist!D54+Hist!D59 -> 8299 | E21: =Hist!E54+Hist!E59 -> 8359 | F21: =Hist!F54+Hist!F59 -> 8227 | G21: =Hist!G54+Hist!G59 -> 9176 | H21: =IS!H6*Assumptions!H23 -> 9992.6538 | I21: =IS!I6*Assumptions!I23 -> 10754.594 | J21: =IS!J6*Assumptions!J23 -> 11684.866 | K21: =IS!K6*Assumptions!K23 -> 12695.607 | L21: =IS!L6*Assumptions!L23 -> 13728.712
A22: Other non-current liabilities (financial, DTL, other) | C22: =Hist!C55+Hist!C56+Hist!C57 -> 3944 | D22: =Hist!D55+Hist!D56+Hist!D57 -> 3778 | E22: =Hist!E55+Hist!E56+Hist!E57 -> 4159 | F22: =Hist!F55+Hist!F56+Hist!F57 -> 4078 | G22: =Hist!G55+Hist!G56+Hist!G57 -> 4332 | H22: =G22 -> 4332 | I22: =H22 -> 4332 | J22: =I22 -> 4332 | K22: =J22 -> 4332 | L22: =K22 -> 4332
A23: Total liabilities | C23: =SUM(C18:C22) -> 42149 | D23: =SUM(D18:D22) -> 50021 | E23: =SUM(E18:E22) -> 49353 | F23: =SUM(F18:F22) -> 52700 | G23: =SUM(G18:G22) -> 62670 | H23: =SUM(H18:H22) -> 67776.644 | I23: =SUM(I18:I22) -> 72183.943 | J23: =SUM(J18:J22) -> 77564.931 | ... L23: =SUM(L18:L22) -> 89387.177
A25: EQUITY
A26: Equity share capital | C26: =Hist!C50 -> 2098 | D26: =Hist!D50 -> 2069 | E26: =Hist!E50 -> 2071 | F26: =Hist!F50 -> 2073 | G26: =Hist!G50 -> 2024 | H26: =G26 -> 2024 | I26: =H26 -> 2024 | J26: =I26 -> 2024 | K26: =J26 -> 2024 | L26: =K26 -> 2024
A27: Other equity | C27: =Hist!C51 -> 73252 | D27: =Hist!D51 -> 73338 | E27: =Hist!E51 -> 86045 | F27: =Hist!F51 -> 93745 | G27: =Hist!G51 -> 90828 | H27: =G27+IS!H25+IS!H29+CF!H24+CF!H25 -> 101386.13 | I27: =H27+IS!I25+IS!I29+CF!I24+CF!I25 -> 112733.42 | J27: =I27+IS!J25+IS!J29+CF!J24+CF!J25 -> 125230.03 | K27: =J27+IS!K25+IS!K29+CF!K24+CF!K25 -> 138927.49 | L27: =K27+IS!L25+IS!L29+CF!L24+CF!L25 -> 153811.32
A28: Equity attributable to owners | C28: =C26+C27 -> 75350 | D28: =D26+D27 -> 75407 | E28: =E26+E27 -> 88116 | F28: =F26+F27 -> 95818 | G28: =G26+G27 -> 92852 | H28: =H26+H27 -> 103410.13 | I28: =I26+I27 -> 114757.42 | J28: =J26+J27 -> 127254.03 | ... L28: =L26+L27 -> 155835.32
A29: Non-controlling interests | C29: =Hist!C52 -> 386 | D29: =Hist!D52 -> 388 | E29: =Hist!E52 -> 345 | F29: =Hist!F52 -> 385 | G29: =Hist!G52 -> 445 | H29: =G29+IS!H24 -> 482.96754 | I29: =H29+IS!I24 -> 523.76641 | J29: =I29+IS!J24 -> 568.7663 | K29: =J29+IS!K24 -> 618.13888 | L29: =K29+IS!L24 -> 671.8164
A30: Total equity | C30: =C28+C29 -> 75736 | D30: =D28+D29 -> 75795 | E30: =E28+E29 -> 88461 | F30: =F28+F29 -> 96203 | G30: =G28+G29 -> 93297 | H30: =H28+H29 -> 103893.1 | I30: =I28+I29 -> 115281.19 | J30: =J28+J29 -> 127822.79 | ... L30: =L28+L29 -> 156507.13
A31: Total liabilities and equity | C31: =C23+C30 -> 117885 | D31: =D23+D30 -> 125816 | E31: =E23+E30 -> 137814 | F31: =F23+F30 -> 148903 | G31: =G23+G30 -> 155967 | H31: =H23+H30 -> 171669.75 | I31: =I23+I30 -> 187465.13 | J31: =J23+J30 -> 205387.72 | ... L31: =L23+L30 -> 245894.31
A32: Balance check (assets − liabilities − equity) | C32: =C15-C31 -> 0 | D32: =D15-D31 -> 0 | E32: =E15-E31 -> 0 | F32: =F15-F31 -> 0 | G32: =G15-G31 -> 0 | H32: =H15-H31 -> 0 | I32: =I15-I31 -> 0 | J32: =J15-J31 -> 0 | ... L32: =L15-L31 -> 0
A34: Memo: net working capital (TR + OCA − TP − OCL) | C34: =C9+C10-C18-C19 -> 12862 | D34: =D9+D10-D18-D19 -> 17233 | E34: =E9+E10-E18-E19 -> 22084 | F34: =F9+F10-F18-F19 -> 21645 | G34: =G9+G10-G18-G19 -> 22985 | H34: =H9+H10-H18-H19 -> 25130.598 | I34: =I9+I10-I18-I19 -> 27046.806 | J34: =J9+J10-J18-J19 -> 29386.355 | ... L34: =L9+L10-L18-L19 -> 34526.438
A35: NWC % revenue | C35: =C34/IS!C6 -> 0.10573737 | D35: =D34/IS!D6 -> 0.1174174 | E35: =E34/IS!E6 -> 0.14371055 | F35: =F34/IS!F6 -> 0.13279956 | G35: =G34/IS!G6 -> 0.12865939 | H35: =H34/IS!H6 -> 0.12826027 | I35: =I34/IS!I6 -> 0.12826027 | J35: =J34/IS!J6 -> 0.12826027 | ... L35: =L34/IS!L6 -> 0.12826027
A36: Memo: new lease additions (non-cash ROU) | H36: =H21-G21-CF!H23 -> 3951.604 | I36: =I21-H21-CF!I23 -> 4135.93 | J36: =J21-I21-CF!J23 -> 4596.1126 | K36: =K21-J21-CF!K23 -> 4993.6764 | L36: =L21-K21-CF!L23 -> 5340.1519
A37: Memo: cash + investments | C37: =C6+C7+C8 -> 37796 | D37: =D6+D7+D8 -> 31651 | E37: =E6+E7+E8 -> 39409 | F37: =F6+F7+F8 -> 47996 | G37: =G6+G7+G8 -> 44081 | H37: =H6+H7+H8 -> 46436.765 | I37: =I6+I7+I8 -> 55065.145 | J37: =J6+J7+J8 -> 64350.743 | ... L37: =L6+L7+L8 -> 85822.504
A38: Memo: trade receivable days (DSO) | C38: =C9/IS!C6*365 -> 68.108368 | D38: =D9/IS!D6*365 -> 63.227837 | E38: =E9/IS!E6*365 -> 71.715006 | F38: =F9/IS!F6*365 -> 69.775262 | G38: =G9/IS!G6*365 -> 71.986622 | H38: =H9/IS!H6*365 -> 72 | I38: =I9/IS!I6*365 -> 72 | J38: =J9/IS!J6*365 -> 72 | ... L38: =L9/IS!L6*365 -> 72

Sheet CF
A1: Infosys Limited — Consolidated Cash Flow Statement
A2: ="₹ crore | Historical columns show reported totals; detail lines are forecast only | Forecast case: "&Assumptions!$E$4 -> ₹ crore | Historical columns show reported totals; detail lines are forecast only | Forecast case: Base case
A4: Fiscal year | C4: FY2022A | D4: FY2023A | E4: FY2024A | F4: FY2025A | G4: FY2026A | H4: FY2027E | I4: FY2028E | J4: FY2029E | K4: FY2030E | L4: FY2031E
A5: OPERATING ACTIVITIES
A6: Profit for the year | H6: =IS!H23 -> 31639.615 | I6: =IS!I23 -> 33999.057 | J6: =IS!J23 -> 37499.914 | K6: =IS!K23 -> 41143.812 | L6: =IS!L23 -> 44731.265
A7: Depreciation and amortisation | H7: =IS!H14 -> 5486.1628 | I7: =IS!I14 -> 5904.4828 | J7: =IS!J14 -> 6415.2205 | K7: =IS!K14 -> 6970.1371 | L7: =IS!L14 -> 7537.332
A8: Stock compensation (non-cash) | H8: =IS!H29 -> 1077.6391 | I8: =IS!I29 -> 1159.8091 | J8: =IS!J29 -> 1260.1326 | K8: =IS!K29 -> 1369.1341 | L8: =IS!L29 -> 1480.5474
A9: (Increase)/decrease in trade receivables | H9: =BS!G9-BS!H9 -> -3416.071 | I9: =BS!H9-BS!I9 -> -2947.0679 | J9: =BS!I9-BS!J9 -> -3598.1525 | K9: =BS!J9-BS!K9 -> -3909.3927 | L9: =BS!K9-BS!L9 -> -3995.8937
A10: (Increase)/decrease in other current assets | H10: =BS!G10-BS!H10 -> -3019.5178 | I10: =BS!H10-BS!I10 -> -2614.4995 | J10: =BS!I10-BS!J10 -> -3192.111 | K10: =BS!J10-BS!K10 -> -3468.2286 | L10: =BS!K10-BS!L10 -> -3544.9682
A11: Increase/(decrease) in trade payables | H11: =BS!H18-BS!G18 -> 546.22846 | I11: =BS!I18-BS!H18 -> 403.37992 | J11: =BS!J18-BS!I18 -> 492.49713 | K11: =BS!K18-BS!J18 -> 535.09813 | L11: =BS!L18-BS!K18 -> 546.93795
A12: Increase/(decrease) in other current liabilities | H12: =BS!H19-BS!G19 -> 3743.7621 | I12: =BS!I19-BS!H19 -> 3241.9794 | J12: =BS!J19-BS!I19 -> 3958.2176 | K12: =BS!K19-BS!J19 -> 4300.6035 | L12: =BS!L19-BS!K19 -> 4395.7605
A13: Change in net working capital | H13: =SUM(H9:H12) -> -2145.5982 | I13: =SUM(I9:I12) -> -1916.2081 | J13: =SUM(J9:J12) -> -2339.5487 | K13: =SUM(K9:K12) -> -2541.9197 | L13: =SUM(L9:L12) -> -2598.1634
A14: Net cash from operating activities | C14: =Hist!C68 -> 23885 | D14: =Hist!D68 -> 22467 | E14: =Hist!E68 -> 25210 | F14: =Hist!F68 -> 35694 | G14: =Hist!G68 -> 33986 | H14: =H6+H7+H8+H13 -> 36057.819 | I14: =I6+I7+I8+I13 -> 39147.141 | J14: =J6+J7+J8+J13 -> 42835.718 | K14: =K6+K7+K8+K13 -> 46941.163 | L14: =L6+L7+L8+L13 -> 51150.981
A16: INVESTING ACTIVITIES
A17: Capital expenditure (PP&E and intangibles) | C17: =Hist!C69 -> -2161 | D17: =Hist!D69 -> -2579 | E17: =Hist!E69 -> -2201 | F17: =Hist!F69 -> -2237 | G17: =Hist!G69 -> -2727 | H17: =-IS!H6*Assumptions!H14 -> -3134.9502 | I17: =-IS!I6*Assumptions!I14 -> -3373.9902 | J17: =-IS!J6*Assumptions!J14 -> -3665.8403 | K17: =-IS!K6*Assumptions!K14 -> -3982.9355 | L17: =-IS!L6*Assumptions!L14 -> -4307.0469
A18: Acquisitions, net of cash acquired | C18: =Hist!C70 -> -53 | D18: =Hist!D70 -> -970 | E18: =Hist!E70 -> -101 | F18: =Hist!F70 -> -3155 | G18: =Hist!G70 -> -650 | H18: =-Assumptions!H30 -> -5311 | I18: =-Assumptions!I30 -> 0 | J18: =-Assumptions!J30 -> 0 | K18: =-Assumptions!K30 -> 0 | L18: =-Assumptions!L30 -> 0
A19: Net (purchase)/sale of investments | H19: =-(BS!H7-BS!G7)-(BS!H8-BS!G8) -> 0 | I19: =-(BS!I7-BS!H7)-(BS!I8-BS!H8) -> 0 | J19: =-(BS!J7-BS!I7)-(BS!J8-BS!I8) -> 0 | K19: =-(BS!K7-BS!J7)-(BS!K8-BS!J8) -> 0 | L19: =-(BS!L7-BS!K7)-(BS!L8-BS!K8) -> 0
A20: Net cash from investing activities | C20: =Hist!C71 -> -6416 | D20: =Hist!D71 -> -1209 | E20: =Hist!E71 -> -5009 | F20: =Hist!F71 -> -1946 | G20: =Hist!G71 -> 1946 | H20: =SUM(H17:H19) -> -8445.9502 | I20: =SUM(I17:I19) -> -3373.9902 | J20: =SUM(J17:J19) -> -3665.8403 | K20: =SUM(K17:K19) -> -3982.9355 | L20: =SUM(L17:L19) -> -4307.0469
A22: FINANCING ACTIVITIES
A23: Payment of lease liabilities (principal) | C23: =Hist!C72 -> -915 | D23: =Hist!D72 -> -1231 | E23: =Hist!E72 -> -2024 | F23: =Hist!F72 -> -2355 | G23: =Hist!G72 -> -2824 | H23: =-IS!H6*Assumptions!H24 -> -3134.9502 | I23: =-IS!I6*Assumptions!I24 -> -3373.9902 | J23: =-IS!J6*Assumptions!J24 -> -3665.8403 | K23: =-IS!K6*Assumptions!K24 -> -3982.9355 | L23: =-IS!L6*Assumptions!L24 -> -4307.0469
A24: Dividends paid | C24: =Hist!C73 -> -12731 | D24: =Hist!D73 -> -13653 | E24: =Hist!E73 -> -14731 | F24: =Hist!F73 -> -20289 | G24: =Hist!G73 -> -18656 | H24: =-IS!H25*Assumptions!H28 -> -22121.153 | I24: =-IS!I25*Assumptions!I28 -> -23770.781 | J24: =-IS!J25*Assumptions!J28 -> -26218.44 | K24: =-IS!K25*Assumptions!K28 -> -28766.107 | L24: =-IS!L25*Assumptions!L28 -> -31274.311
A25: Share buybacks | C25: =Hist!C74 -> -11125 | D25: =Hist!D74 -> -11499 | E25: =Hist!E74 -> 0 | F25: =Hist!F74 -> 0 | G25: =Hist!G74 -> -18058 | H25: =-Assumptions!H29 -> 0 | I25: =-Assumptions!I29 -> 0 | J25: =-Assumptions!J29 -> 0 | K25: =-Assumptions!K29 -> 0 | L25: =-Assumptions!L29 -> 0
A26: Net cash from financing activities | C26: =Hist!C75 -> -24642 | D26: =Hist!D75 -> -26695 | E26: =Hist!E75 -> -17504 | F26: =Hist!F75 -> -24161 | G26: =Hist!G75 -> -39786 | H26: =SUM(H23:H25) -> -25256.103 | I26: =SUM(I23:I25) -> -27144.771 | J26: =SUM(J23:J25) -> -29884.28 | K26: =SUM(K23:K25) -> -32749.043 | L26: =SUM(L23:L25) -> -35581.358
A28: Net change in cash | C28: =C14+C20+C26 -> -7173 | D28: =D14+D20+D26 -> -5437 | E28: =E14+E20+E26 -> 2697 | F28: =F14+F20+F26 -> 9587 | G28: =G14+G20+G26 -> -3854 | H28: =H14+H20+H26 -> 2355.7652 | I28: =I14+I20+I26 -> 8628.3798 | J28: =J14+J20+J26 -> 9285.5978 | ... L28: =L14+L20+L26 -> 11262.576
A29: Effect of exchange rate changes on cash | C29: =Hist!C76 -> -69 | D29: =Hist!D76 -> 138 | E29: =Hist!E76 -> -84 | F29: =Hist!F76 -> 82 | G29: =Hist!G76 -> 1600 | H29: 0 | I29: 0 | J29: 0 | K29: 0 | L29: 0
A30: Opening cash and cash equivalents | C30: =Hist!C77 -> 24714 | D30: =Hist!D77 -> 17472 | E30: =Hist!E77 -> 12173 | F30: =Hist!F77 -> 14786 | G30: =Hist!G77 -> 24455 | H30: =G31 -> 22201 | I30: =H31 -> 24556.765 | J30: =I31 -> 33185.145 | K30: =J31 -> 42470.743 | L30: =K31 -> 52679.928
A31: Closing cash and cash equivalents | C31: =C30+C28+C29 -> 17472 | D31: =D30+D28+D29 -> 12173 | E31: =E30+E28+E29 -> 14786 | F31: =F30+F28+F29 -> 24455 | G31: =G30+G28+G29 -> 22201 | H31: =H30+H28+H29 -> 24556.765 | I31: =I30+I28+I29 -> 33185.145 | J31: =J30+J28+J29 -> 42470.743 | ... L31: =L30+L28+L29 -> 63942.504
A33: Memo: free cash flow (CFO + capex) | C33: =C14+C17 -> 21724 | D33: =D14+D17 -> 19888 | E33: =E14+E17 -> 23009 | F33: =F14+F17 -> 33457 | G33: =G14+G17 -> 31259 | H33: =H14+H17 -> 32922.869 | I33: =I14+I17 -> 35773.151 | J33: =J14+J17 -> 39169.878 | ... L33: =L14+L17 -> 46843.934
A34: FCF % of profit for the year | C34: =C33/IS!C23 -> 0.98094464 | D34: =D33/IS!D23 -> 0.82495437 | E34: =E33/IS!E23 -> 0.87660012 | F34: =F33/IS!F23 -> 1.250729 | G34: =G33/IS!G23 -> 1.0605619 | H34: =H33/IS!H23 -> 1.0405584 | I34: =I33/IS!I23 -> 1.0521807 | J34: =J33/IS!J23 -> 1.0445325 | ... L34: =L33/IS!L23 -> 1.0472303

Sheet WACC
A1: Infosys Limited — Weighted Average Cost of Capital
A2: INR-denominated CAPM | Blue = input; green = link to another sheet; black = formula
A4: COST OF EQUITY
A5: Risk-free rate (India 10-year G-sec yield) | D5: 0.074
A6: Equity beta (vs Nifty 50) | D6: 0.85
A7: Equity risk premium (India, INR) | D7: 0.06
A8: Cost of equity (CAPM) | D8: =D5+D6*D7 -> 0.125
A10: COST OF DEBT (lease liabilities — Infosys has no borrowings)
A11: Pre-tax cost of lease liabilities | D11: =Assumptions!H26 -> 0.05
A12: Tax rate (FY27E, live case) | D12: =Assumptions!H16 -> 0.275
A13: After-tax cost of debt | D13: =D11*(1-D12) -> 0.03625
A15: CAPITAL STRUCTURE (market values, ₹ crore)
A16: Current share price (₹) | D16: =DCF!D7 -> 1153.35
A17: Diluted shares (crore) | D17: =Hist!C87 -> 405.26865
A18: Market capitalisation | D18: =D16*D17 -> 467416.6
A19: Debt-like: lease liabilities (31-Mar-2026) | D19: =BS!G21 -> 9176
A20: Total capital | D20: =D18+D19 -> 476592.6
A21: Equity weight | D21: =D18/D20 -> 0.98074666
A22: Debt weight | D22: =D19/D20 -> 0.019253341
A24: WACC
A25: Weighted average cost of capital | D25: =D21*D8+D22*D13 -> 0.12329127

Sheet DCF
A1: Infosys Limited — Discounted Cash Flow Valuation
A2: ="₹ crore unless stated | Unlevered FCF, mid-year convention, perpetuity-growth terminal value | Case: "&Assumptions!$E$4 -> ₹ crore unless stated | Unlevered FCF, mid-year convention, perpetuity-growth terminal value | Case: Base case
A4: MARKET DATA & VALUATION INPUTS
A5: Valuation base date (latest audited balance sheet) | D5: =DATE(2026,3,31) -> 46112
A6: Valuation date | D6: =DATE(2026,10,23) -> 46318
A7: Current share price, NSE (₹) | D7: 1153.35
A8: Diluted shares (crore) | D8: =Hist!C87 -> 405.26865
A9: WACC | D9: =WACC!D25 -> 0.12329127
A10: Terminal growth rate (INR, perpetual) | D10: 0.05
A11: Cost of equity (for roll-forward) | D11: =WACC!D8 -> 0.125
A14: UNLEVERED FREE CASH FLOW
A15: ₹ crore | G15: FY2026A | H15: FY2027E | I15: FY2028E | J15: FY2029E | K15: FY2030E | L15: FY2031E
A16: Revenue | G16: =IS!G6 -> 178650 | H16: =IS!H6 -> 195934.39 | I16: =IS!I6 -> 210874.38 | J16: =IS!J6 -> 229115.02 | K16: =IS!K6 -> 248933.47 | L16: =IS!L6 -> 269190.43
A17: EBIT | G17: =IS!G15 -> 37378 | H17: =IS!H15 -> 41146.221 | I17: =IS!I15 -> 44283.621 | J17: =IS!J15 -> 48572.384 | K17: =IS!K15 -> 53022.829 | L17: =IS!L15 -> 57337.561
A18: EBIT margin | G18: =G17/G16 -> 0.20922474 | H18: =H17/H16 -> 0.21 | I18: =I17/I16 -> 0.21 | J18: =J17/J16 -> 0.212 | K18: =K17/K16 -> 0.213 | L18: =L17/L16 -> 0.213
A19: Less: tax on EBIT | H19: =-H17*Assumptions!H16 -> -11315.211 | I19: =-I17*Assumptions!I16 -> -12177.996 | J19: =-J17*Assumptions!J16 -> -13357.406 | K19: =-K17*Assumptions!K16 -> -14581.278 | L19: =-L17*Assumptions!L16 -> -15767.829
A20: NOPAT | H20: =H17+H19 -> 29831.01 | I20: =I17+I19 -> 32105.625 | J20: =J17+J19 -> 35214.978 | K20: =K17+K19 -> 38441.551 | L20: =L17+L19 -> 41569.732
A21: Add: depreciation and amortisation | H21: =IS!H14 -> 5486.1628 | I21: =IS!I14 -> 5904.4828 | J21: =IS!J14 -> 6415.2205 | K21: =IS!K14 -> 6970.1371 | L21: =IS!L14 -> 7537.332
A22: Less: capital expenditure | H22: =CF!H17 -> -3134.9502 | I22: =CF!I17 -> -3373.9902 | J22: =CF!J17 -> -3665.8403 | K22: =CF!K17 -> -3982.9355 | L22: =CF!L17 -> -4307.0469
A23: Less: new lease additions (ROU, debt-like capex) | H23: =-BS!H36 -> -3951.604 | I23: =-BS!I36 -> -4135.93 | J23: =-BS!J36 -> -4596.1126 | K23: =-BS!K36 -> -4993.6764 | L23: =-BS!L36 -> -5340.1519
A24: Less: increase in net working capital | H24: =CF!H13 -> -2145.5982 | I24: =CF!I13 -> -1916.2081 | J24: =CF!J13 -> -2339.5487 | K24: =CF!K13 -> -2541.9197 | L24: =CF!L13 -> -2598.1634
A25: Unlevered free cash flow | H25: =H20+H21+H22+H23+H24 -> 26085.021 | I25: =I20+I21+I22+I23+I24 -> 28583.98 | J25: =J20+J21+J22+J23+J24 -> 31028.697 | K25: =K20+K21+K22+K23+K24 -> 33893.156 | L25: =L20+L21+L22+L23+L24 -> 36861.702
A26: UFCF margin | H26: =H25/H16 -> 0.13313141 | I26: =I25/I16 -> 0.13554979 | J26: =J25/J16 -> 0.13542847 | K26: =K25/K16 -> 0.13615347 | L26: =L25/L16 -> 0.13693541
A27: Discount period (years from base date, mid-year) | H27: =YEARFRAC($D$5,DATE(YEAR($D$5)+1,MONTH($D$5),DAY($D$5)),1)/2 -> 0.5 | I27: =H27+1 -> 1.5 | J27: =I27+1 -> 2.5 | K27: =J27+1 -> 3.5 | L27: =K27+1 -> 4.5
A28: Discount factor | H28: =1/(1+$D$9)^H27 -> 0.94352586 | I28: =1/(1+$D$9)^I27 -> 0.83996546 | J28: =1/(1+$D$9)^J27 -> 0.74777173 | K28: =1/(1+$D$9)^K27 -> 0.6656971 | L28: =1/(1+$D$9)^L27 -> 0.59263088
A29: PV of unlevered FCF | H29: =H25*H28 -> 24611.892 | I29: =I25*I28 -> 24009.555 | J29: =J25*J28 -> 23202.383 | K29: =K25*K28 -> 22562.576 | L29: =L25*L28 -> 21845.383
A31: TERMINAL VALUE (perpetuity growth)
A32: Final-year unlevered FCF (FY2031E) | D32: =L25 -> 36861.702
A33: Terminal-year FCF (× (1 + g)) | D33: =D32*(1+D10) -> 38704.787
A34: Terminal value at FY2031 | D34: =D33/(D9-D10) -> 528095.49
A35: Discount factor (mid-year, consistent with FY2031E) | D35: =L28 -> 0.59263088
A36: PV of terminal value | D36: =D34*D35 -> 312965.7
A37: Implied terminal EV / FY2031E EBITDA (x) | D37: =D34/IS!L12 -> 8.1402136
A39: ENTERPRISE VALUE TO EQUITY VALUE BRIDGE
A40: Sum of PV of unlevered FCF | D40: =SUM(H29:L29) -> 116231.79
A41: PV of terminal value | D41: =D36 -> 312965.7
A42: Enterprise value | D42: =D40+D41 -> 429197.49
A43: Terminal value % of EV | D43: =D41/D42 -> 0.72918809
A44: Add: cash and cash equivalents (31-Mar-2026) | D44: =BS!G6 -> 22201
A45: Add: current investments | D45: =BS!G7 -> 12950
...

Sheet Sources
A1: Sources & References
A3: Item | B3: Used in | C3: Source
A4: FY2026A & FY2025A IS / BS / CF (Ind AS consolidated) | B4: Hist columns F:G | C4: Infosys Form 6-K Ex. 99.3, results for year ended 31-Mar-2026 — https://www.sec.gov/Archives/edgar/data/0001067491/000106749126000014/exv99w03.htm
A5: FY2024A & FY2023A IS / BS / CF | B5: Hist columns D:E | C5: Infosys Form 6-K Ex. 99.3, results for year ended 31-Mar-2024 — https://www.sec.gov/Archives/edgar/data/1067491/000106749124000014/exv99w03.htm
A6: FY2022A IS / BS / CF | B6: Hist column C | C6: Infosys Form 6-K Ex. 99.3, results for year ended 31-Mar-2023 (comparative year) — https://www.sec.gov/Archives/edgar/data/1067491/000106749123000025/exv99w03.htm
A7: Q1 FY27 revenue, net profit, diluted EPS, CC growth, FY27 guidance | B7: Hist rows 83–92 | C7: Infosys IFRS-INR press release, 23-Jul-2026 — https://www.sec.gov/Archives/edgar/data/0001067491/000106749126000038/exv99w02.htm
A8: FY26 CC growth 3.1%, yield on cash 6.7% | B8: Hist row 93; Assumptions row 25 | C8: Infosys Q4 FY26 earnings call transcript — https://www.infosys.com/investors/reports-filings/quarterly-results/2025-2026/q4/documents/transcripts/earningscall.pdf
A9: Optimum (~₹4,410 cr) & Stratus (~₹901 cr) acquisitions; FY26 final dividend ₹25 | B9: Hist rows 94–96; DCF bridge | C9: FY2026 results release notes 1(h) and 2 (first link above)
A10: Share price ₹1,153.35 (NSE close 22-Oct-2026) | B10: DCF!D7 | C10: Unofficial aggregator — Tickertape https://www.tickertape.in/stocks/infosys-INFY (corroborated by Trendlyne). Refresh from NSE.
A11: India 10-year G-sec yield ~7.4% | B11: WACC!D5 | C11: Unofficial — Trading Economics (7.47%, 23-Oct-2026) https://tradingeconomics.com/india/government-bond-yield; Investing.com (7.39%, 19-Oct-2026). Analyst assumption.
A12: Beta 0.85, ERP 6.0%, terminal growth 5.0%, all forecast drivers | B12: WACC, DCF, Assumptions | C12: Analyst assumptions (not sourced data); rationale summarised on Cover.

Sheet Checks
A1: Infosys Limited — Model Integrity Checks
A2: Differences in ₹ crore; each line should be zero (tolerance ±0.5)
A3: MASTER CHECK | C3: =IF(COUNTIF(M5:M19,"ERROR")=0,"✓ ALL CHECKS PASS","✗ ERRORS — REVIEW BELOW") -> ✓ ALL CHECKS PASS
A4: Check | C4: FY2022A | D4: FY2023A | E4: FY2024A | F4: FY2025A | G4: FY2026A | H4: FY2027E | I4: FY2028E | J4: FY2029E | K4: FY2030E | L4: FY2031E | M4: Status
A5: Balance sheet balances (assets − liabilities − equity) | C5: =BS!C32 -> 0 | D5: =BS!D32 -> 0 | E5: =BS!E32 -> 0 | F5: =BS!F32 -> 0 | G5: =BS!G32 -> 0 | H5: =BS!H32 -> 0 | I5: =BS!I32 -> 0 | J5: =BS!J32 -> 0 | ... L5: =BS!L32 -> 0 | M5: {=IF(SUMPRODUCT(ABS(N(+C5:L5)))<0.5,"OK","ERROR")} -> OK
A6: Cash tie-out (CF closing cash − BS cash) | C6: =CF!C31-BS!C6 -> 0 | D6: =CF!D31-BS!D6 -> 0 | E6: =CF!E31-BS!E6 -> 0 | F6: =CF!F31-BS!F6 -> 0 | G6: =CF!G31-BS!G6 -> 0 | H6: =CF!H31-BS!H6 -> 0 | I6: =CF!I31-BS!I6 -> 0 | J6: =CF!J31-BS!J6 -> 0 | ... L6: =CF!L31-BS!L6 -> 0 | M6: {=IF(SUMPRODUCT(ABS(N(+C6:L6)))<0.5,"OK","ERROR")} -> OK
A7: Historical: model PBT − reported PBT | C7: =IS!C30 -> 0 | D7: =IS!D30 -> 0 | E7: =IS!E30 -> 0 | F7: =IS!F30 -> 0 | G7: =IS!G30 -> 0 | M7: {=IF(SUMPRODUCT(ABS(N(+C7:L7)))<0.5,"OK","ERROR")} -> OK
A8: Historical: model total assets − reported total assets | C8: =BS!C15-Hist!C48 -> 0 | D8: =BS!D15-Hist!D48 -> 0 | E8: =BS!E15-Hist!E48 -> 0 | F8: =BS!F15-Hist!F48 -> 0 | G8: =BS!G15-Hist!G48 -> 0 | M8: {=IF(SUMPRODUCT(ABS(N(+C8:L8)))<0.5,"OK","ERROR")} -> OK
A9: Historical: model total L&E − reported total L&E | C9: =BS!C31-Hist!C65 -> 0 | D9: =BS!D31-Hist!D65 -> 0 | E9: =BS!E31-Hist!E65 -> 0 | F9: =BS!F31-Hist!F65 -> 0 | G9: =BS!G31-Hist!G65 -> 0 | M9: {=IF(SUMPRODUCT(ABS(N(+C9:L9)))<0.5,"OK","ERROR")} -> OK
A10: Historical: rebuilt closing cash − reported closing cash | C10: =CF!C31-Hist!C78 -> 0 | D10: =CF!D31-Hist!D78 -> 0 | E10: =CF!E31-Hist!E78 -> 0 | F10: =CF!F31-Hist!F78 -> 0 | G10: =CF!G31-Hist!G78 -> 0 | M10: {=IF(SUMPRODUCT(ABS(N(+C10:L10)))<0.5,"OK","ERROR")} -> OK
A11: Historical: opening cash = prior-year closing cash | D11: =CF!D30-CF!C31 -> 0 | E11: =CF!E30-CF!D31 -> 0 | F11: =CF!F30-CF!E31 -> 0 | G11: =CF!G30-CF!F31 -> 0 | M11: {=IF(SUMPRODUCT(ABS(N(+C11:L11)))<0.5,"OK","ERROR")} -> OK
A12: Forecast: CF profit = IS profit for the year | H12: =CF!H6-IS!H23 -> 0 | I12: =CF!I6-IS!I23 -> 0 | J12: =CF!J6-IS!J23 -> 0 | K12: =CF!K6-IS!K23 -> 0 | L12: =CF!L6-IS!L23 -> 0 | M12: {=IF(SUMPRODUCT(ABS(N(+C12:L12)))<0.5,"OK","ERROR")} -> OK
A13: Forecast: equity roll-forward (opening + profit + SBC − dividends − buybacks − closing) | H13: =BS!G30+IS!H23+IS!H29+CF!H24+CF!H25-BS!H30 -> 0 | I13: =BS!H30+IS!I23+IS!I29+CF!I24+CF!I25-BS!I30 -> 0 | J13: =BS!I30+IS!J23+IS!J29+CF!J24+CF!J25-BS!J30 -> 0 | K13: =BS!J30+IS!K23+IS!K29+CF!K24+CF!K25-BS!K30 -> 0 | L13: =BS!K30+IS!L23+IS!L29+CF!L24+CF!L25-BS!L30 -> 0 | M13: {=IF(SUMPRODUCT(ABS(N(+C13:L13)))<0.5,"OK","ERROR")} -> OK
A14: Forecast: opening cash = prior-year closing cash | H14: =CF!H30-CF!G31 -> 0 | I14: =CF!I30-CF!H31 -> 0 | J14: =CF!J30-CF!I31 -> 0 | K14: =CF!K30-CF!J31 -> 0 | L14: =CF!L30-CF!K31 -> 0 | M14: {=IF(SUMPRODUCT(ABS(N(+C14:L14)))<0.5,"OK","ERROR")} -> OK
A15: Forecast: DCF revenue = IS revenue | H15: =DCF!H16-IS!H6 -> 0 | I15: =DCF!I16-IS!I6 -> 0 | J15: =DCF!J16-IS!J6 -> 0 | K15: =DCF!K16-IS!K6 -> 0 | L15: =DCF!L16-IS!L6 -> 0 | M15: {=IF(SUMPRODUCT(ABS(N(+C15:L15)))<0.5,"OK","ERROR")} -> OK
A16: Terminal growth below WACC | C16: =IF(DCF!D10<DCF!D9,0,1) -> 0 | M16: =IF(ABS(C16)<0.5,"OK","ERROR") -> OK
A17: Sensitivity table centres equal implied value per share | C17: =DCF!D100 -> 0 | M17: =IF(ABS(C17)<0.5,"OK","ERROR") -> OK
A18: Forecast fixed-asset and cash balances non-negative | C18: =IF(AND(MIN(BS!H12:L12)>0,MIN(BS!H6:L6)>=0),0,1) -> 0 | M18: =IF(ABS(C18)<0.5,"OK","ERROR") -> OK
A19: Scenario selector valid (1, 2 or 3) | C19: =IF(OR(Assumptions!D4=1,Assumptions!D4=2,Assumptions!D4=3),0,1) -> 0 | M19: =IF(ABS(C19)<0.5,"OK","ERROR") -> OK
